Run python update.py
  
Traceback (most recent call last):
  File "/home/runner/work/Textme/Textme/update.py", line 7, in <module>
    from google.genai.errors import APIError, ResourceExhaustedError, InternalError
ImportError: cannot import name 'ResourceExhaustedError' from 'google.genai.errors' (/opt/hostedtoolcache/Python/3.10.18/x64/lib/python3.10/site-packages/google/genai/errors.py)
Error: Process completed with exit code 1.
